{"name": "test_receive_failure_notification", "status": "failed", "statusDetails": {"message": "AssertionError: No se encontró notificación específica de fallo entre las notificaciones\nassert False", "trace": "tests\\test_notifications.py:42: in test_receive_failure_notification\n    assert failure_notification_found, \"No se encontró notificación específica de fallo entre las notificaciones\"\nE   AssertionError: No se encontró notificación específica de fallo entre las notificaciones\nE   assert False"}, "description": "\n        P2 #1: Recibir notificación cuando falla la entrega\n        ", "start": 1760553945502, "stop": 1760553957402, "uuid": "edf4ca85-0183-40bc-914a-bdd8a1fec039", "historyId": "680553b39e3df9464fa6b21a7c09dc19", "testCaseId": "680553b39e3df9464fa6b21a7c09dc19", "fullName": "tests.test_notifications.TestNotifications#test_receive_failure_notification", "labels": [{"name": "tag", "value": "test_id('P2-001')"}, {"name": "parentSuite", "value": "tests"}, {"name": "suite", "value": "test_notifications"}, {"name": "subSuite", "value": "TestNotifications"}, {"name": "host", "value": "L43429"}, {"name": "thread", "value": "5772-MainThread"}, {"name": "framework", "value": "pytest"}, {"name": "language", "value": "cpython3"}, {"name": "package", "value": "tests.test_notifications"}]}