{"name": "test_consult_failure_evidence", "status": "failed", "statusDetails": {"message": "Failed: ScopeMismatch: You tried to access the function scoped fixture base_url with a session scoped request object, involved factories:\n.venv\\Lib\\site-packages\\pytest_base_url\\plugin.py:18:  def _verify_url(request, base_url)\ntests\\conftest.py:29:  def base_url()", "trace": "ScopeMismatch: You tried to access the function scoped fixture base_url with a session scoped request object, involved factories:\n.venv\\Lib\\site-packages\\pytest_base_url\\plugin.py:18:  def _verify_url(request, base_url)\ntests\\conftest.py:29:  def base_url()"}, "description": "\n        P2 #11: Consultar evidencia del fallo\n        ", "start": 1760549903231, "stop": 1760549903231, "uuid": "b45624e1-6d3a-429a-ab04-631ed1ad2ec8", "historyId": "47986703edd062e88f4248f914968db9", "testCaseId": "47986703edd062e88f4248f914968db9", "fullName": "tests.test_notifications.TestNotifications#test_consult_failure_evidence", "labels": [{"name": "tag", "value": "test_id('P2-011')"}, {"name": "parentSuite", "value": "tests"}, {"name": "suite", "value": "test_notifications"}, {"name": "subSuite", "value": "TestNotifications"}, {"name": "host", "value": "L43429"}, {"name": "thread", "value": "17604-MainThread"}, {"name": "framework", "value": "pytest"}, {"name": "language", "value": "cpython3"}, {"name": "package", "value": "tests.test_notifications"}]}